<?xml version="1.0"?>
<robot name="simple">   
 <material name="blue">        
<color rgba="0 0 0.8 1"/>   
 </material>    
<material name="white">        <color rgba="1 1 1 1"/>    </material> 
   <link name="base_link">        
<visual>            <origin rpy="0 0 0" xyz="0 0 0"/>
            <geometry>                <cylinder radius="0.2" length="0.6"/>            </geometry>            <material name="blue"/>        </visual>    </link>    
<link name="right_leg">        <visual>            <origin rpy="0 0 0" xyz="0 0 -0.3"/>            <geometry>                <box size="0.2 0.1 0.6"/>            </geometry>            <material name="white"/>        </visual>    </link>

    <joint name="base_to_right_leg" type="revolute">
        <parent link="base_link"/>        
	<child link="right_leg"/>       
	<origin xyz="0 -0.22 0.25" rpy="0 0 0"/>
        <limit lower="-0.2" upper="0.2" effort="0.1" velocity="0.005"/>
        <axis xyz="0 1 0"/>
	<origin xyz="0 -0.22 0.25" rpy="0 1.571 0"/>
    </joint>
</robot>
